Workbook

Sheet 說明
B2: 美國公債期貨 基差 / IRR / 部位損益 試算模型
B3: 依 BofA Global Research《Primer: US Treasury futures and basis》(2025/7/10) 之定義建構
B5: 一、色彩圖例（哪些格子可以改）
B6: 藍色字 | C6: 輸入值（直接手動修改） | D6: 期貨價格、乾淨價、轉換因子、票息、repo、付息日
B7: 黑色字 | C7: 公式（請勿覆寫） | D7: IRR、毛基差、淨基差、carry、損益
B8: 綠色字 | C8: 跨工作表連結 | D8: 由『基差試算』帶入『部位損益』『交割情境』
B9: 黃色底 | C9: 關鍵假設 | D9: 期貨價格、交割日、repo 利率、計息基準
B11: 二、三張工作表的用途
B12: 基差試算 | C12: 輸入期貨價格、可交割券的乾淨價與轉換因子、實際 repo，算出每一檔的毛基差、carry、淨基差、隱含附買回利率(IRR)，並自動標出最便宜交割券(CTD)。
B13: 部位損益 | C13: 設定買基差／賣基差的方向與名目金額，輸入出場時的乾淨價與期貨價，拆解現貨腿、票息、repo 成本、期貨腿的損益，並與「持有至交割」的理論損益對照。
B14: 交割情境 | C14: 模仿 Bloomberg CMS 畫面：平行移動殖利率 ±100bp，重算交割日各券遠期價格與基差，檢視 CTD 是否轉換、以及基差的類選擇權(straddle)報酬型態。
B16: 三、符號定義（先講白話，再上公式）
B17: 符號 | C17: 意義 | D17: 說明
B18: F | C18: 期貨價格 | D18: 以小數表示。108-07¾ 需先換算為 108 + 7.75/32 = 108.242188
B19: c | C19: 轉換因子 (conversion factor) | D19: 該券以 6% 殖利率計價的價格，合約存續期間固定不變
B20: B | C20: 乾淨價 (clean price) | D20: 不含應計利息的市場報價
B21: AI | C21: 應計利息 (accrued interest) | D21: 採 actual/actual：票息/2 × (結算日−上次付息日)/(付息期天數)
B22: 全價 | C22: ＝ B + AI | D22: 實際付出的現金，也是計算融資成本與 IRR 的基礎
B23: 發票金額 | C23: ＝ c × F + AI(交割日) | D23: 空方交券時實際收到的每 100 面額金額
B24: 毛基差 | C24: ＝ B − c × F | D24: 用「現貨」乾淨價；市場報價的基差就是這一個
B25: carry | C25: ＝ 票息收入 + 再投資 − repo 融資成本 | D25: 持有到交割日的淨持有收益
B26: 淨基差 | C26: ＝ 遠期乾淨價 − c × F ＝ 毛基差 − carry | D26: 交割選擇權的市場價格
B27: IRR | C27: 隱含附買回利率 (implied repo rate) | D27: 買現貨、持有、交割進期貨所實現的年化報酬率
B28: CTD | C28: 最便宜交割券 | D28: 淨基差最低（等價於 IRR 最高）的那一檔
B30: 四、模型使用的完整公式（逐檔債券）
B31: ① 現貨應計利息 AI_s = 票息/2 × (現貨交割日 − 上次付息日) ÷ (下次付息日 − 上次付息日)
B32: ② 現貨全價 P = B + AI_s
B33: ③ 交割日應計利息 AI_d：若交割日已過下次付息日，改用下一個付息期間計算，並認列期間收到的票息 C = 票息/2
B34: ④ 發票金額 = c × F + AI_d
B35: ⑤ 毛基差 = B − c × F （×32 換成 tick）
B36: ⑥ 融資成本 = P × repo × (交割日 − 現貨交割日) ÷ 360
B37: ⑦ carry = (AI_d − AI_s + C + C×repo×n_c/360) − 融資成本
B38: ⑧ 遠期全價 = P × (1 + repo×n/360) − C × (1 + repo×n_c/360)；遠期乾淨價 = 遠期全價 − AI_d
B39: ⑨ 淨基差 = 遠期乾淨價 − c × F（恆等於 毛基差 − carry，模型內有交叉檢核）
B40: ⑩ IRR = (發票金額 + C − P) ÷ ( P×n/360 − C×n_c/360 ) ← 票息以 IRR 本身再投資的精確解
B41: ⑪ 持有至交割的理論損益 = −(淨基差) × 面額 ÷ 100（買基差方向）
... B48: • 交割情境表使用 Excel 內建 PRICE/YIELD 函數重算遠期價格，屬近似的平行移動情境，未納入曲線扭轉與 wild card 選擇權。

Sheet 基差試算
A1: 基差 / IRR 試算表
A2: 藍色 = 可輸入；黃底 = 關鍵假設；黑色 = 公式，請勿覆寫
A3: 一、契約參數
A4: 契約代碼 | B4: FVU5 | D4: 例：FVU5 = 2025年9月 5年期(CME: ZF)
A5: 期貨價格 F（小數） | B5: 108.24219 | D5: 108-07¾ → 108 + 7.75/32
A6: 合約規模（每口面額 $） | B6: 100000 | D6: TU/ZT 為 200,000，其餘為 100,000
A7: 現貨交割日 (Settle) | B7: 45846 | D7: 買入現貨的交割日
A8: 期貨交割日 (Delivery) | B8: 45902 | D8: 正 carry 假設末日、負 carry 假設首日
A9: 持有天數 n | B9: =B8-B7 -> 56 | D9: 現貨交割日 → 期貨交割日
A10: 實際 Repo 利率 | B10: 0.0434 | D10: 一般擔保品 (GC) 利率，逐檔可另設
A11: Repo 計息基準（天/年） | B11: 360 | D11: Act/360 輸入 360；Act/365 輸入 365
A12: 票息頻率（次/年） | B12: 2 | D12: 美國公債固定為 2
A15: 二、可交割券明細（藍色欄位為輸入；A~I 欄可自行增刪列）
A16: # | B16: 可交割券 | C16: 到期日 | D16: 票息 % | E16: 乾淨價 B | F16: 轉換因子 c | G16: 上次付息日 | H16: 下次付息日 | I16: 該券 Repo | J16: 再下次付息日 | K16: 現貨應計 AI_s | L16: 現貨全價 P | M16: 交割日應計 AI_d | N16: 期間票息 C | O16: 票息→交割天數 | P16: 發票金額 | Q16: 毛基差(點) | R16: 毛基差(32nds) | S16: 融資成本 | T16: Carry(點) | U16: 遠期全價 | V16: 遠期乾淨價 | W16: 淨基差(點) | X16: 淨基差(32nds) | Y16: IRR | Z16: Repo−IRR(bp) | AA16: CTD | AB16: 檢核
A17: 1 | B17: T 4⅛ 11/30/29 | C17: 47452 | D17: 4.125 | E17: 100.77734 | F17: 0.9317 | G17: 45808 | H17: 45991 | I17: =$B$10 -> 0.0434 | J17: =IF(H17=EOMONTH(H17,0),EOMONTH(H17,6),EDATE(H17,6)) -> 46173 | K17: =D17/$B$12*($B$7-G17)/(H17-G17) -> 0.42827869 | L17: =E17+K17 -> 101.20562 | M17: =IF($B$8<=H17,D17/$B$12*($B$8-G17)/(H17-G17),D17/$B$12*($B$8-H17)/(J17-H17)) -> 1.0594262 | N17: =IF($B$8<=H17,0,D17/$B$12) -> 0 | O17: =IF(N17=0,0,$B$8-H17) -> 0 | P17: =F17*$B$5+M17 -> 101.90867 | Q17: =E17-F17*$B$5 -> -0.071902344 | R17: =Q17*32 -> -2.300875 | S17: =L17*I17*($B$8-$B$7)/$B$11 -> 0.6832504 | T17: =(M17-K17+N17+N17*I17*O17/$B$11)-S17 -> -0.052102861 | U17: =L17*(1+I17*($B$8-$B$7)/$B$11)-N17*(1+I17*O17/$B$11) -> 101.88887 | V17: =U17-M17 -> 100.82945 | W17: =V17-F17*$B$5 -> -0.019799483 | X17: =W17*32 -> -0.63358344 | Y17: =(P17+N17-L17)/(L17*($B$8-$B$7)/$B$11-N17*O17/$B$11) -> 0.044657661 | Z17: =(I17-Y17)*10000 -> -12.576612 | AA17: =IF(X17=MIN($X$17:$X$24),"★ CTD","") -> ★ CTD | AB17: =IF(ABS((Q17-T17)-W17)<0.000001,"OK","檢查") -> OK
A18: 2 | B18: T 4⅜ 12/31/29 | C18: 47483 | D18: 4.375 | E18: 101.75 | F18: 0.9397 | G18: 45838 | H18: 46022 | I18: =$B$10 -> 0.0434 | J18: =IF(H18=EOMONTH(H18,0),EOMONTH(H18,6),EDATE(H18,6)) -> 46203 | K18: =D18/$B$12*($B$7-G18)/(H18-G18) -> 0.095108696 | L18: =E18+K18 -> 101.84511 | M18: =IF($B$8<=H18,D18/$B$12*($B$8-G18)/(H18-G18),D18/$B$12*($B$8-H18)/(J18-H18)) -> 0.76086957 | N18: =IF($B$8<=H18,0,D18/$B$12) -> 0 | O18: =IF(N18=0,0,$B$8-H18) -> 0 | P18: =F18*$B$5+M18 -> 102.47605 | Q18: =E18-F18*$B$5 -> 0.034816406 | R18: =Q18*32 -> 1.114125 | S18: =L18*I18*($B$8-$B$7)/$B$11 -> 0.68756764 | T18: =(M18-K18+N18+N18*I18*O18/$B$11)-S18 -> -0.021806775 | U18: =L18*(1+I18*($B$8-$B$7)/$B$11)-N18*(1+I18*O18/$B$11) -> 102.53268 | V18: =U18-M18 -> 101.77181 | W18: =V18-F18*$B$5 -> 0.056623182 | X18: =W18*32 -> 1.8119418 | Y18: =(P18+N18-L18)/(L18*($B$8-$B$7)/$B$11-N18*O18/$B$11) -> 0.039825885 | Z18: =(I18-Y18)*10000 -> 35.741154 | AA18: =IF(X18=MIN($X$17:$X$24),"★ CTD","") | AB18: =IF(ABS((Q18-T18)-W18)<0.000001,"OK","檢查") -> OK
A19: 3 | B19: T 4¼ 01/31/30 | C19: 47514 | D19: 4.25 | E19: 101.23047 | F19: 0.934 | G19: 45688 | H19: 45869 | I19: =$B$10 -> 0.0434 | J19: =IF(H19=EOMONTH(H19,0),EOMONTH(H19,6),EDATE(H19,6)) -> 46053 | K19: =D19/$B$12*($B$7-G19)/(H19-G19) -> 1.8549724 | L19: =E19+K19 -> 103.08544 | M19: =IF($B$8<=H19,D19/$B$12*($B$8-G19)/(H19-G19),D19/$B$12*($B$8-H19)/(J19-H19)) -> 0.38111413 | N19: =IF($B$8<=H19,0,D19/$B$12) -> 2.125 | O19: =IF(N19=0,0,$B$8-H19) -> 33 | P19: =F19*$B$5+M19 -> 101.47932 | Q19: =E19-F19*$B$5 -> 0.13226562 | R19: =Q19*32 -> 4.2325 | S19: =L19*I19*($B$8-$B$7)/$B$11 -> 0.69594127 | T19: =(M19-K19+N19+N19*I19*O19/$B$11)-S19 -> -0.036345554 | U19: =L19*(1+I19*($B$8-$B$7)/$B$11)-N19*(1+I19*O19/$B$11) -> 101.64793 | V19: =U19-M19 -> 101.26681 | W19: =V19-F19*$B$5 -> 0.16861118 | X19: =W19*32 -> 5.3955577 | Y19: =(P19+N19-L19)/(L19*($B$8-$B$7)/$B$11-N19*O19/$B$11) -> 0.03275584 | Z19: =(I19-Y19)*10000 -> 106.4416 | AA19: =IF(X19=MIN($X$17:$X$24),"★ CTD","") | AB19: =IF(ABS((Q19-T19)-W19)<0.000001,"OK","檢查") -> OK
A20: 4 | B20: T 4 02/28/30 | C20: 47542 | D20: 4 | E20: 100.24609 | F20: 0.9234 | G20: 45716 | H20: 45900 | I20: =$B$10 -> 0.0434 | J20: =IF(H20=EOMONTH(H20,0),EOMONTH(H20,6),EDATE(H20,6)) -> 46081 | K20: =D20/$B$12*($B$7-G20)/(H20-G20) -> 1.4130435 | L20: =E20+K20 -> 101.65914 | M20: =IF($B$8<=H20,D20/$B$12*($B$8-G20)/(H20-G20),D20/$B$12*($B$8-H20)/(J20-H20)) -> 0.022099448 | N20: =IF($B$8<=H20,0,D20/$B$12) -> 2 | O20: =IF(N20=0,0,$B$8-H20) -> 2 | P20: =F20*$B$5+M20 -> 99.972935 | Q20: =E20-F20*$B$5 -> 0.29525781 | R20: =Q20*32 -> 9.44825 | S20: =L20*I20*($B$8-$B$7)/$B$11 -> 0.68631213 | T20: =(M20-K20+N20+N20*I20*O20/$B$11)-S20 -> -0.076773939 | U20: =L20*(1+I20*($B$8-$B$7)/$B$11)-N20*(1+I20*O20/$B$11) -> 100.34497 | V20: =U20-M20 -> 100.32287 | W20: =V20-F20*$B$5 -> 0.37203175 | X20: =W20*32 -> 11.905016 | Y20: =(P20+N20-L20)/(L20*($B$8-$B$7)/$B$11-N20*O20/$B$11) -> 0.01985746 | Z20: =(I20-Y20)*10000 -> 235.4254 | AA20: =IF(X20=MIN($X$17:$X$24),"★ CTD","") | AB20: =IF(ABS((Q20-T20)-W20)<0.000001,"OK","檢查") -> OK
A21: 5 | B21: T 4 03/31/30 | C21: 47573 | D21: 4 | E21: 100.16797 | F21: 0.9221 | G21: 45747 | H21: 45930 | I21: =$B$10 -> 0.0434 | J21: =IF(H21=EOMONTH(H21,0),EOMONTH(H21,6),EDATE(H21,6)) -> 46112 | K21: =D21/$B$12*($B$7-G21)/(H21-G21) -> 1.0819672 | L21: =E21+K21 -> 101.24994 | M21: =IF($B$8<=H21,D21/$B$12*($B$8-G21)/(H21-G21),D21/$B$12*($B$8-H21)/(J21-H21)) -> 1.6939891 | N21: =IF($B$8<=H21,0,D21/$B$12) -> 0 | O21: =IF(N21=0,0,$B$8-H21) -> 0 | P21: =F21*$B$5+M21 -> 101.50411 | Q21: =E21-F21*$B$5 -> 0.35784766 | R21: =Q21*32 -> 11.451125 | S21: =L21*I21*($B$8-$B$7)/$B$11 -> 0.68354957 | T21: =(M21-K21+N21+N21*I21*O21/$B$11)-S21 -> -0.07152771 | U21: =L21*(1+I21*($B$8-$B$7)/$B$11)-N21*(1+I21*O21/$B$11) -> 101.93349 | V21: =U21-M21 -> 100.2395 | W21: =V21-F21*$B$5 -> 0.42937537 | X21: =W21*32 -> 13.740012 | Y21: =(P21+N21-L21)/(L21*($B$8-$B$7)/$B$11-N21*O21/$B$11) -> 0.016138055 | Z21: =(I21-Y21)*10000 -> 272.61945 | AA21: =IF(X21=MIN($X$17:$X$24),"★ CTD","") | AB21: =IF(ABS((Q21-T21)-W21)<0.000001,"OK","檢查") -> OK
A22: 6 | B22: T 3⅞ 04/30/30 | C22: 47603 | D22: 3.875 | E22: 99.640625 | F22: 0.9159 | G22: 45777 | H22: 45961 | I22: =$B$10 -> 0.0434 | J22: =IF(H22=EOMONTH(H22,0),EOMONTH(H22,6),EDATE(H22,6)) -> 46142 | K22: =D22/$B$12*($B$7-G22)/(H22-G22) -> 0.7265625 | L22: =E22+K22 -> 100.36719 | M22: =IF($B$8<=H22,D22/$B$12*($B$8-G22)/(H22-G22),D22/$B$12*($B$8-H22)/(J22-H22)) -> 1.3162364 | N22: =IF($B$8<=H22,0,D22/$B$12) -> 0 | O22: =IF(N22=0,0,$B$8-H22) -> 0 | P22: =F22*$B$5+M22 -> 100.45526 | Q22: =E22-F22*$B$5 -> 0.50160547 | R22: =Q22*32 -> 16.051375 | S22: =L22*I22*($B$8-$B$7)/$B$11 -> 0.67759003 | T22: =(M22-K22+N22+N22*I22*O22/$B$11)-S22 -> -0.087916122 | U22: =L22*(1+I22*($B$8-$B$7)/$B$11)-N22*(1+I22*O22/$B$11) -> 101.04478 | V22: =U22-M22 -> 99.728541 | W22: =V22-F22*$B$5 -> 0.58952159 | X22: =W22*32 -> 18.864691 | Y22: =(P22+N22-L22)/(L22*($B$8-$B$7)/$B$11-N22*O22/$B$11) -> 0.0056408304 | Z22: =(I22-Y22)*10000 -> 377.5917 | AA22: =IF(X22=MIN($X$17:$X$24),"★ CTD","") | AB22: =IF(ABS((Q22-T22)-W22)<0.000001,"OK","檢查") -> OK
A23: 7 | B23: T 4 05/31/30 | C23: 47634 | D23: 4 | E23: 100.19922 | F23: 0.9196 | G23: 45808 | H23: 45991 | I23: =$B$10 -> 0.0434 | J23: =IF(H23=EOMONTH(H23,0),EOMONTH(H23,6),EDATE(H23,6)) -> 46173 | K23: =D23/$B$12*($B$7-G23)/(H23-G23) -> 0.41530055 | L23: =E23+K23 -> 100.61452 | M23: =IF($B$8<=H23,D23/$B$12*($B$8-G23)/(H23-G23),D23/$B$12*($B$8-H23)/(J23-H23)) -> 1.0273224 | N23: =IF($B$8<=H23,0,D23/$B$12) -> 0 | O23: =IF(N23=0,0,$B$8-H23) -> 0 | P23: =F23*$B$5+M23 -> 100.56684 | Q23: =E23-F23*$B$5 -> 0.65970313 | R23: =Q23*32 -> 21.1105 | S23: =L23*I23*($B$8-$B$7)/$B$11 -> 0.6792598 | T23: =(M23-K23+N23+N23*I23*O23/$B$11)-S23 -> -0.067237941 | U23: =L23*(1+I23*($B$8-$B$7)/$B$11)-N23*(1+I23*O23/$B$11) -> 101.29378 | V23: =U23-M23 -> 100.26646 | W23: =V23-F23*$B$5 -> 0.72694107 | X23: =W23*32 -> 23.262114 | Y23: =(P23+N23-L23)/(L23*($B$8-$B$7)/$B$11-N23*O23/$B$11) -> -0.003046503 | Z23: =(I23-Y23)*10000 -> 464.46503 | AA23: =IF(X23=MIN($X$17:$X$24),"★ CTD","") | AB23: =IF(ABS((Q23-T23)-W23)<0.000001,"OK","檢查") -> OK
A24: 8 | B24: T 3⅞ 06/30/30 | C24: 47664 | D24: 3.875 | E24: 99.59375 | F24: 0.9132 | G24: 45838 | H24: 46022 | I24: =$B$10 -> 0.0434 | J24: =IF(H24=EOMONTH(H24,0),EOMONTH(H24,6),EDATE(H24,6)) -> 46203 | K24: =D24/$B$12*($B$7-G24)/(H24-G24) -> 0.08423913 | L24: =E24+K24 -> 99.677989 | M24: =IF($B$8<=H24,D24/$B$12*($B$8-G24)/(H24-G24),D24/$B$12*($B$8-H24)/(J24-H24)) -> 0.67391304 | N24: =IF($B$8<=H24,0,D24/$B$12) -> 0 | O24: =IF(N24=0,0,$B$8-H24) -> 0 | P24: =F24*$B$5+M24 -> 99.520679 | Q24: =E24-F24*$B$5 -> 0.74698437 | R24: =Q24*32 -> 23.9035 | S24: =L24*I24*($B$8-$B$7)/$B$11 -> 0.67293718 | T24: =(M24-K24+N24+N24*I24*O24/$B$11)-S24 -> -0.083263267 | U24: =L24*(1+I24*($B$8-$B$7)/$B$11)-N24*(1+I24*O24/$B$11) -> 100.35093 | V24: =U24-M24 -> 99.677013 | W24: =V24-F24*$B$5 -> 0.83024764 | X24: =W24*32 -> 26.567925 | Y24: =(P24+N24-L24)/(L24*($B$8-$B$7)/$B$11-N24*O24/$B$11) -> -0.010145485 | Z24: =(I24-Y24)*10000 -> 535.45485 | AA24: =IF(X24=MIN($X$17:$X$24),"★ CTD","") | AB24: =IF(ABS((Q24-T24)-W24)<0.000001,"OK","檢查") -> OK
A26: 三、CTD 判定摘要
A27: 最便宜交割券 (CTD) | B27: =INDEX($B$17:$B$24,MATCH(MIN($X$17:$X$24),$X$17:$X$24,0)) -> T 4⅛ 11/30/29
A28: CTD 淨基差 (32nds) | B28: =MIN($X$17:$X$24) -> -0.63358344
A29: CTD 毛基差 (32nds) | B29: =INDEX($R$17:$R$24,MATCH(MIN($X$17:$X$24),$X$17:$X$24,0)) -> -2.300875
A30: CTD 隱含附買回利率 IRR | B30: =INDEX($Y$17:$Y$24,MATCH(MIN($X$17:$X$24),$X$17:$X$24,0)) -> 0.044657661
A31: 籃中最高 IRR（應等於上一列） | B31: =MAX($Y$17:$Y$24) -> 0.044657661
A32: CTD 轉換因子 c | B32: =INDEX($F$17:$F$24,MATCH(MIN($X$17:$X$24),$X$17:$X$24,0)) -> 0.9317
A33: 隱含期貨價 = CTD 遠期乾淨價 / c | B33: =INDEX($V$17:$V$24,MATCH(MIN($X$17:$X$24),$X$17:$X$24,0))/INDEX($F$17:$F$24,MATCH(MIN($X$17:$X$24),$X$17:$X$24,0)) -> 108.22094
A34: 每 tick 價值（每口，$） | B34: =$B$6/100/32 -> 31.25
A35: 註：淨基差最低 = IRR 最高，兩種判定必然一致；若不一致代表各券 repo 輸入不同。

Sheet 部位損益
A1: 基差部位損益試算
A2: 設定方向與名目金額，輸入出場價格，即可拆解四段損益來源
A4: 一、部位設定
A5: 選擇債券（輸入 1~8） | B5: 1 | D5: 對應『基差試算』表中的序號
A6: 方向（買基差 = 1；賣基差 = -1） | B6: 1 | D6: 買基差 = 買現貨 + 空期貨 = 買進交割選擇權
A7: 現貨名目面額 ($) | B7: 100000000 | D7: 例：$100mm
A8: 進場日（現貨交割日） | B8: =基差試算!B7 -> 45846 | D8: 由參數區帶入
A9: 出場日 | B9: 45884 | D9: 若等於期貨交割日即為持有至交割
A10: 出場乾淨價 B₁ | B10: 101 | D10: 現貨賣出時的乾淨價
A11: 出場期貨價 F₁ | B11: 108.5 | D11: 期貨回補時的價格
A13: 二、由『基差試算』帶入的進場條件
A14: 債券名稱 | B14: =INDEX(基差試算!$B$17:$B$24,$B$5) -> T 4⅛ 11/30/29
A15: 票息 (%) | B15: =INDEX(基差試算!$D$17:$D$24,$B$5) -> 4.125
A16: 轉換因子 c | B16: =INDEX(基差試算!$F$17:$F$24,$B$5) -> 0.9317
A17: 進場乾淨價 B₀ | B17: =INDEX(基差試算!$E$17:$E$24,$B$5) -> 100.77734
A18: 進場期貨價 F₀ | B18: =基差試算!$B$5 -> 108.24219
A19: 進場現貨全價 P₀ | B19: =INDEX(基差試算!$L$17:$L$24,$B$5) -> 101.20562
A20: Repo 利率 | B20: =INDEX(基差試算!$I$17:$I$24,$B$5) -> 0.0434
A21: 進場毛基差 (32nds) | B21: =INDEX(基差試算!$R$17:$R$24,$B$5) -> -2.300875
A22: 進場淨基差 (32nds) | B22: =INDEX(基差試算!$X$17:$X$24,$B$5) -> -0.63358344
A23: 上次付息日 | B23: =INDEX(基差試算!$G$17:$G$24,$B$5) -> 45808
A24: 下次付息日 | B24: =INDEX(基差試算!$H$17:$H$24,$B$5) -> 45991
A25: 再下次付息日 | B25: =INDEX(基差試算!$J$17:$J$24,$B$5) -> 46173
A27: 三、部位規模
A28: 期貨口數（轉換因子加權，四捨五入） | B28: =ROUND($B$7*$B$16/基差試算!$B$6,0) -> 932
A29: 期貨名目金額 ($) | B29: =B28*基差試算!$B$6 -> 93200000
A30: 尾差 tail（現貨 − 期貨名目，$） | B30: =$B$7-B29 -> 6800000
A31: 每 1 tick 基差變動的損益 ($) | B31: =$B$7/100/32 -> 31250
A33: 四、持有期間中間計算
A34: 持有天數 | B34: =$B$9-$B$8 -> 38
A35: 出場日應計利息 AI₁ | B35: =IF($B$9<=$B$24,$B$15/2*($B$9-$B$23)/($B$24-$B$23),$B$15/2*($B$9-$B$24)/($B$25-$B$24)) -> 0.85655738
A36: 進場日應計利息 AI₀ | B36: =$B$19-$B$17 -> 0.42827869
A37: 期間收到票息 C | B37: =IF($B$9<=$B$24,0,$B$15/2) -> 0
A38: 票息→出場天數 | B38: =IF(B37=0,0,$B$9-$B$24) -> 0
A40: 五、損益拆解
A41: 損益來源 | B41: 金額 ($) | D41: 說明
A42: ① 現貨資本利得 | B42: =$B$6*($B$10-$B$17)*$B$7/100 -> 222656.25 | D42: (出場乾淨價 − 進場乾淨價) × 面額/100
A43: ② 票息收入（含再投資） | B43: =$B$6*($B$35-$B$36+$B$37+$B$37*$B$20*$B$38/基差試算!$B$11)*$B$7/100 -> 428278.69 | D43: 應計利息增加 + 期間票息 + 票息再投資
A44: ③ Repo 融資成本 | B44: =-$B$6*$B$19*$B$20*$B$34/基差試算!$B$11*$B$7/100 -> -463634.2 | D44: 以全價融資；買基差為成本、賣基差為收益
A45: ④ 期貨腿損益 | B45: =-$B$6*($B$11-$B$18)*$B$28*基差試算!$B$6/100 -> -240281.25 | D45: 買基差 = 空期貨，期貨漲則虧
...

Sheet 交割情境
A1: 交割日情境分析（平行移動 ±100bp）
A2: 模仿 Bloomberg CMS 畫面：在交割日將各券殖利率平行移動，重算遠期價格，取 F* = MIN(B/c)，再算各券基差
A4: 一、情境設定（bp）
B5: 殖利率變動 (bp) → | F5: -100 | G5: -50 | H5: 0 | I5: 50 | J5: 100
A7: # | B7: 可交割券 | C7: 到期日 | D7: 遠期乾淨價 | E7: 遠期殖利率 | F7: 價格 -100bp | G7: 價格 -50bp | H7: 價格 +0bp | I7: 價格 +50bp | J7: 價格 +100bp | K7: B/c -100bp | L7: B/c -50bp | M7: B/c +0bp | N7: B/c +50bp | O7: B/c +100bp | P7: 基差 -100bp (32nds) | Q7: 基差 -50bp (32nds) | R7: 基差 +0bp (32nds) | S7: 基差 +50bp (32nds) | T7: 基差 +100bp (32nds)
A8: 1 | B8: =基差試算!B17 -> T 4⅛ 11/30/29 | C8: =基差試算!C17 -> 47452 | D8: =基差試算!V17 -> 100.82945 | E8: =YIELD(基差試算!$B$8,C8,基差試算!D17/100,D8,100,2,1) -> 0.039096722 | F8: =PRICE(基差試算!$B$8,$C8,基差試算!D17/100,$E8+F$5/10000,100,2,1) -> 104.81464 | G8: =PRICE(基差試算!$B$8,$C8,基差試算!D17/100,$E8+G$5/10000,100,2,1) -> 102.7994 | H8: =PRICE(基差試算!$B$8,$C8,基差試算!D17/100,$E8+H$5/10000,100,2,1) -> 100.82945 | I8: =PRICE(基差試算!$B$8,$C8,基差試算!D17/100,$E8+I$5/10000,100,2,1) -> 98.90364 | J8: =PRICE(基差試算!$B$8,$C8,基差試算!D17/100,$E8+J$5/10000,100,2,1) -> 97.020874 | K8: =F8/基差試算!F17 -> 112.49827 | L8: =G8/基差試算!F17 -> 110.3353 | M8: =H8/基差試算!F17 -> 108.22094 | N8: =I8/基差試算!F17 -> 106.15395 | O8: =J8/基差試算!F17 -> 104.13317 | P8: =(F8-基差試算!F17*K$16)*32 -> 0 | Q8: =(G8-基差試算!F17*L$16)*32 -> 0 | R8: =(H8-基差試算!F17*M$16)*32 -> 0 | S8: =(I8-基差試算!F17*N$16)*32 -> 0 | T8: =(J8-基差試算!F17*O$16)*32 -> 0
A9: 2 | B9: =基差試算!B18 -> T 4⅜ 12/31/29 | C9: =基差試算!C18 -> 47483 | D9: =基差試算!V18 -> 101.77181 | E9: =YIELD(基差試算!$B$8,C9,基差試算!D18/100,D9,100,2,1) -> 0.039244691 | F9: =PRICE(基差試算!$B$8,$C9,基差試算!D18/100,$E9+F$5/10000,100,2,1) -> 105.85074 | G9: =PRICE(基差試算!$B$8,$C9,基差試算!D18/100,$E9+G$5/10000,100,2,1) -> 103.78774 | H9: =PRICE(基差試算!$B$8,$C9,基差試算!D18/100,$E9+H$5/10000,100,2,1) -> 101.77181 | I9: =PRICE(基差試算!$B$8,$C9,基差試算!D18/100,$E9+I$5/10000,100,2,1) -> 99.801733 | J9: =PRICE(基差試算!$B$8,$C9,基差試算!D18/100,$E9+J$5/10000,100,2,1) -> 97.876357 | K9: =F9/基差試算!F18 -> 112.64312 | L9: =G9/基差試算!F18 -> 110.44774 | M9: =H9/基差試算!F18 -> 108.30244 | N9: =I9/基差試算!F18 -> 106.20595 | O9: =J9/基差試算!F18 -> 104.15703 | P9: =(F9-基差試算!F18*K$16)*32 -> 4.3558383 | Q9: =(G9-基差試算!F18*L$16)*32 -> 3.3811705 | R9: =(H9-基差試算!F18*M$16)*32 -> 2.4509655 | S9: =(I9-基差試算!F18*N$16)*32 -> 1.5635595 | T9: =(J9-基差試算!F18*O$16)*32 -> 0.71734879
A10: 3 | B10: =基差試算!B19 -> T 4¼ 01/31/30 | C10: =基差試算!C19 -> 47514 | D10: =基差試算!V19 -> 101.26681 | E10: =YIELD(基差試算!$B$8,C10,基差試算!D19/100,D10,100,2,1) -> 0.039335603 | F10: =PRICE(基差試算!$B$8,$C10,基差試算!D19/100,$E10+F$5/10000,100,2,1) -> 105.40669 | G10: =PRICE(基差試算!$B$8,$C10,基差試算!D19/100,$E10+G$5/10000,100,2,1) -> 103.31245 | H10: =PRICE(基差試算!$B$8,$C10,基差試算!D19/100,$E10+H$5/10000,100,2,1) -> 101.26681 | I10: =PRICE(基差試算!$B$8,$C10,基差試算!D19/100,$E10+I$5/10000,100,2,1) -> 99.268531 | J10: =PRICE(基差試算!$B$8,$C10,基差試算!D19/100,$E10+J$5/10000,100,2,1) -> 97.316376 | K10: =F10/基差試算!F19 -> 112.85513 | L10: =G10/基差試算!F19 -> 110.6129 | M10: =H10/基差試算!F19 -> 108.42271 | N10: =I10/基差試算!F19 -> 106.28322 | O10: =J10/基差試算!F19 -> 104.19312 | P10: =(F10-基差試算!F19*K$16)*32 -> 10.665783 | Q10: =(G10-基差試算!F19*L$16)*32 -> 8.2968502 | R10: =(H10-基差試算!F19*M$16)*32 -> 6.0307052 | S10: =(I10-基差試算!F19*N$16)*32 -> 3.8635829 | T10: =(J10-基差試算!F19*O$16)*32 -> 1.7918529
A11: 4 | B11: =基差試算!B20 -> T 4 02/28/30 | C11: =基差試算!C20 -> 47542 | D11: =基差試算!V20 -> 100.32287 | E11: =YIELD(基差試算!$B$8,C11,基差試算!D20/100,D11,100,2,1) -> 0.039208961 | F11: =PRICE(基差試算!$B$8,$C11,基差試算!D20/100,$E11+F$5/10000,100,2,1) -> 104.51421 | G11: =PRICE(基差試算!$B$8,$C11,基差試算!D20/100,$E11+G$5/10000,100,2,1) -> 102.39348 | H11: =PRICE(基差試算!$B$8,$C11,基差試算!D20/100,$E11+H$5/10000,100,2,1) -> 100.32287 | I11: =PRICE(基差試算!$B$8,$C11,基差試算!D20/100,$E11+I$5/10000,100,2,1) -> 98.301049 | J11: =PRICE(基差試算!$B$8,$C11,基差試算!D20/100,$E11+J$5/10000,100,2,1) -> 96.326747 | K11: =F11/基差試算!F20 -> 113.18411 | L11: =G11/基差試算!F20 -> 110.88746 | M11: =H11/基差試算!F20 -> 108.64508 | N11: =I11/基差試算!F20 -> 106.45554 | O11: =J11/基差試算!F20 -> 104.31747 | P11: =(F11-基差試算!F20*K$16)*32 -> 20.265764 | Q11: =(G11-基差試算!F20*L$16)*32 -> 16.31565 | R11: =(H11-基差試算!F20*M$16)*32 -> 12.532955 | S11: =(I11-基差試算!F20*N$16)*32 -> 8.9115958 | T11: =(J11-基差試算!F20*O$16)*32 -> 5.4457056
A12: 5 | B12: =基差試算!B21 -> T 4 03/31/30 | C12: =基差試算!C21 -> 47573 | D12: =基差試算!V21 -> 100.2395 | E12: =YIELD(基差試算!$B$8,C12,基差試算!D21/100,D12,100,2,1) -> 0.039416829 | F12: =PRICE(基差試算!$B$8,$C12,基差試算!D21/100,$E12+F$5/10000,100,2,1) -> 104.49878 | G12: =PRICE(基差試算!$B$8,$C12,基差試算!D21/100,$E12+G$5/10000,100,2,1) -> 102.34328 | H12: =PRICE(基差試算!$B$8,$C12,基差試算!D21/100,$E12+H$5/10000,100,2,1) -> 100.2395 | I12: =PRICE(基差試算!$B$8,$C12,基差試算!D21/100,$E12+I$5/10000,100,2,1) -> 98.186058 | J12: =PRICE(基差試算!$B$8,$C12,基差試算!D21/100,$E12+J$5/10000,100,2,1) -> 96.181622 | K12: =F12/基差試算!F21 -> 113.32695 | L12: =G12/基差試算!F21 -> 110.98935 | M12: =H12/基差試算!F21 -> 108.70784 | N12: =I12/基差試算!F21 -> 106.48092 | O12: =J12/基差試算!F21 -> 104.30715 | P12: =(F12-基差試算!F21*K$16)*32 -> 24.451936 | Q12: =(G12-基差試算!F21*L$16)*32 -> 19.299053 | R12: =(H12-基差試算!F21*M$16)*32 -> 14.367067 | S12: =(I12-基差試算!F21*N$16)*32 -> 9.6478683 | T12: =(J12-基差試算!F21*O$16)*32 -> 5.1336408
A13: 6 | B13: =基差試算!B22 -> T 3⅞ 04/30/30 | C13: =基差試算!C22 -> 47603 | D13: =基差試算!V22 -> 99.728541 | E13: =YIELD(基差試算!$B$8,C13,基差試算!D22/100,D13,100,2,1) -> 0.039383516 | F13: =PRICE(基差試算!$B$8,$C13,基差試算!D22/100,$E13+F$5/10000,100,2,1) -> 104.04862 | G13: =PRICE(基差試算!$B$8,$C13,基差試算!D22/100,$E13+G$5/10000,100,2,1) -> 101.86191 | H13: =PRICE(基差試算!$B$8,$C13,基差試算!D22/100,$E13+H$5/10000,100,2,1) -> 99.728541 | I13: =PRICE(基差試算!$B$8,$C13,基差試算!D22/100,$E13+I$5/10000,100,2,1) -> 97.64706 | J13: =PRICE(基差試算!$B$8,$C13,基差試算!D22/100,$E13+J$5/10000,100,2,1) -> 95.616069 | K13: =F13/基差試算!F22 -> 113.6026 | L13: =G13/基差試算!F22 -> 111.2151 | M13: =H13/基差試算!F22 -> 108.88584 | N13: =I13/基差試算!F22 -> 106.61323 | O13: =J13/基差試算!F22 -> 104.39575 | P13: =(F13-基差試算!F22*K$16)*32 -> 32.366529 | Q13: =(G13-基差試算!F22*L$16)*32 -> 25.785945 | R13: =(H13-基差試算!F22*M$16)*32 -> 19.48753 | S13: =(I13-基差試算!F22*N$16)*32 -> 13.460877 | T13: =(J13-基差試算!F22*O$16)*32 -> 7.6959565
A14: 7 | B14: =基差試算!B23 -> T 4 05/31/30 | C14: =基差試算!C23 -> 47634 | D14: =基差試算!V23 -> 100.26646 | E14: =YIELD(基差試算!$B$8,C14,基差試算!D23/100,D14,100,2,1) -> 0.0393673 | F14: =PRICE(基差試算!$B$8,$C14,基差試算!D23/100,$E14+F$5/10000,100,2,1) -> 104.67222 | G14: =PRICE(基差試算!$B$8,$C14,基差試算!D23/100,$E14+G$5/10000,100,2,1) -> 102.44174 | H14: =PRICE(基差試算!$B$8,$C14,基差試算!D23/100,$E14+H$5/10000,100,2,1) -> 100.26646 | I14: =PRICE(基差試算!$B$8,$C14,基差試算!D23/100,$E14+I$5/10000,100,2,1) -> 98.144846 | J14: =PRICE(基差試算!$B$8,$C14,基差試算!D23/100,$E14+J$5/10000,100,2,1) -> 96.075443 | K14: =F14/基差試算!F23 -> 113.82364 | L14: =G14/基差試算!F23 -> 111.39816 | M14: =H14/基差試算!F23 -> 109.03268 | N14: =I14/基差試算!F23 -> 106.72558 | O14: =J14/基差試算!F23 -> 104.47525 | P14: =(F14-基差試算!F23*K$16)*32 -> 39.001941 | Q14: =(G14-基差試算!F23*L$16)*32 -> 31.276805 | R14: =(H14-基差試算!F23*M$16)*32 -> 23.887469 | S14: =(I14-基差試算!F23*N$16)*32 -> 16.82141 | T14: =(J14-基差試算!F23*O$16)*32 -> 10.06656
A15: 8 | B15: =基差試算!B24 -> T 3⅞ 06/30/30 | C15: =基差試算!C24 -> 47664 | D15: =基差試算!V24 -> 99.677013 | E15: =YIELD(基差試算!$B$8,C15,基差試算!D24/100,D15,100,2,1) -> 0.039481747 | F15: =PRICE(基差試算!$B$8,$C15,基差試算!D24/100,$E15+F$5/10000,100,2,1) -> 104.13776 | G15: =PRICE(基差試算!$B$8,$C15,基差試算!D24/100,$E15+G$5/10000,100,2,1) -> 101.879 | H15: =PRICE(基差試算!$B$8,$C15,基差試算!D24/100,$E15+H$5/10000,100,2,1) -> 99.677013 | I15: =PRICE(基差試算!$B$8,$C15,基差試算!D24/100,$E15+I$5/10000,100,2,1) -> 97.530225 | J15: =PRICE(基差試算!$B$8,$C15,基差試算!D24/100,$E15+J$5/10000,100,2,1) -> 95.437103 | K15: =F15/基差試算!F24 -> 114.03609 | L15: =G15/基差試算!F24 -> 111.56263 | M15: =H15/基差試算!F24 -> 109.15135 | N15: =I15/基差試算!F24 -> 106.80051 | O15: =J15/基差試算!F24 -> 104.50843 | P15: =(F15-基差試算!F24*K$16)*32 -> 44.938764 | Q15: =(G15-基差試算!F24*L$16)*32 -> 35.865593 | R15: =(H15-基差試算!F24*M$16)*32 -> 27.188927 | S15: =(I15-基差試算!F24*N$16)*32 -> 18.893887 | T15: =(J15-基差試算!F24*O$16)*32 -> 10.966139
B16: F* = MIN(B/c) | K16: =MIN(K8:K15) -> 112.49827 | L16: =MIN(L8:L15) -> 110.3353 | M16: =MIN(M8:M15) -> 108.22094 | N16: =MIN(N8:N15) -> 106.15395 | O16: =MIN(O8:O15) -> 104.13317
B17: 該情境 CTD | K17: =INDEX($B$8:$B$15,MATCH(MIN(K8:K15),K8:K15,0)) -> T 4⅛ 11/30/29 | L17: =INDEX($B$8:$B$15,MATCH(MIN(L8:L15),L8:L15,0)) -> T 4⅛ 11/30/29 | M17: =INDEX($B$8:$B$15,MATCH(MIN(M8:M15),M8:M15,0)) -> T 4⅛ 11/30/29 | N17: =INDEX($B$8:$B$15,MATCH(MIN(N8:N15),N8:N15,0)) -> T 4⅛ 11/30/29 | O17: =INDEX($B$8:$B$15,MATCH(MIN(O8:O15),O8:O15,0)) -> T 4⅛ 11/30/29 | P17: =INDEX($B$8:$B$15,MATCH(MIN(K8:K15),K8:K15,0)) -> T 4⅛ 11/30/29 | Q17: =INDEX($B$8:$B$15,MATCH(MIN(L8:L15),L8:L15,0)) -> T 4⅛ 11/30/29 | R17: =INDEX($B$8:$B$15,MATCH(MIN(M8:M15),M8:M15,0)) -> T 4⅛ 11/30/29 | S17: =INDEX($B$8:$B$15,MATCH(MIN(N8:N15),N8:N15,0)) -> T 4⅛ 11/30/29 | T17: =INDEX($B$8:$B$15,MATCH(MIN(O8:O15),O8:O15,0)) -> T 4⅛ 11/30/29
B19: • 解讀：基差欄位顯示「該券在交割日、該殖利率情境下的基差（32nds）」。CTD 的基差恆為 0，其餘各券為正。
B20: • 若今日 CTD 在 ±50bp 情境下基差由 0 變正，代表 CTD 已轉換 —— 多方基差部位在兩端都獲利，報酬型態近似買進利率跨式(straddle)。
B21: • 本表使用 Excel 內建 PRICE/YIELD（actual/actual、半年付息）重算價格，屬平行移動近似；曲線扭轉與 wild card 選擇權未納入。
B22: • 第 5 列的 bp 數字可自行修改。以本範例（5年期籃、殖利率約 3.95%）為例，±100bp 之內 CTD 都維持在最短天期的 11/30/29；把情境改成 +150bp 會切換到 01/31/30，+200bp 以上則切換到最長天期的 06/30/30 —— 正好印證「殖利率低於 6% 時低存續期間券為 CTD、高於 6% 時高存續期間券為 CTD」。
